Traceback (most recent call last):
  File "/home/tycho/snap/anaconda3/envs/jupyterbook/lib/python3.10/site-packages/jupyter_cache/executors/utils.py", line 58, in single_nb_execution
    executenb(
  File "/home/tycho/snap/anaconda3/envs/jupyterbook/lib/python3.10/site-packages/nbclient/client.py", line 1319, in execute
    return NotebookClient(nb=nb, resources=resources, km=km, **kwargs).execute()
  File "/home/tycho/snap/anaconda3/envs/jupyterbook/lib/python3.10/site-packages/jupyter_core/utils/__init__.py", line 165, in wrapped
    return loop.run_until_complete(inner)
  File "/home/tycho/snap/anaconda3/envs/jupyterbook/lib/python3.10/asyncio/base_events.py", line 649, in run_until_complete
    return future.result()
  File "/home/tycho/snap/anaconda3/envs/jupyterbook/lib/python3.10/site-packages/nbclient/client.py", line 709, in async_execute
    await self.async_execute_cell(
  File "/home/tycho/snap/anaconda3/envs/jupyterbook/lib/python3.10/site-packages/nbclient/client.py", line 1062, in async_execute_cell
    await self._check_raise_for_error(cell, cell_index, exec_reply)
  File "/home/tycho/snap/anaconda3/envs/jupyterbook/lib/python3.10/site-packages/nbclient/client.py", line 918, in _check_raise_for_error
    raise CellExecutionError.from_cell_and_msg(cell, exec_reply_content)
nbclient.exceptions.CellExecutionError: An error occurred while executing the following cell:
------------------
import networkx as nx
import matplotlib.pyplot as plt

# Create a graph object
G = nx.Graph()

# Add nodes (concepts)
G.add_node("Main Topic")
G.add_node("Subtopic 1")
G.add_node("Subtopic 2")
G.add_node("Detail 1.1")

# Add edges (connections between nodes)
G.add_edges_from(
    [
        ("Main Topic", "Subtopic 1"),
        ("Main Topic", "Subtopic 2"),
        ("Subtopic 1", "Detail 1.1"),
    ]
)

# Draw the graph
nx.draw(G, with_labels=True, node_color="lightblue", node_size=3000, font_size=12)
plt.show()

------------------


[0;31m---------------------------------------------------------------------------[0m
[0;31mModuleNotFoundError[0m                       Traceback (most recent call last)
Cell [0;32mIn[1], line 1[0m
[0;32m----> 1[0m [38;5;28;01mimport[39;00m[38;5;250m [39m[38;5;21;01mnetworkx[39;00m[38;5;250m [39m[38;5;28;01mas[39;00m[38;5;250m [39m[38;5;21;01mnx[39;00m
[1;32m      2[0m [38;5;28;01mimport[39;00m[38;5;250m [39m[38;5;21;01mmatplotlib[39;00m[38;5;21;01m.[39;00m[38;5;21;01mpyplot[39;00m[38;5;250m [39m[38;5;28;01mas[39;00m[38;5;250m [39m[38;5;21;01mplt[39;00m
[1;32m      4[0m [38;5;66;03m# Create a graph object[39;00m

[0;31mModuleNotFoundError[0m: No module named 'networkx'

